[2024-06-16T02:00:37.047+0200] {scheduler_job_runner.py:769} ERROR - Executor reports task instance <TaskInstance: datalake_dag.format_consumption_data scheduled__2024-06-15T00:00:00+00:00 [queued]> finished (failed) although the task says it's queued. (Info: None) Was the task killed externally?
